Workbook

Sheet MAL
A1: SECTION | B1: X - SIGNED OUT, Y ASSIGNED, Z AVAILABLE | C1: WPN | D1: IDENTIFIER | E1: RANK | F1: LASTNAME | G1: FIRSTNAME | H1: PRIMARY WEAPON | I1: SERIAL | J1: OPTIC | K1: SERIAL | L1: PEQ | M1: SERIAL | N1: NODS | O1: SERIAL | P1: NOTES | Q1: ADDITIONAL SI
A2: SCT | B2: x | C2: M4 | D2: 1 | E2: 1LT | F2: MILLIGAN | G2: ROBERT | H2: M4 | I2: W010240 | J2: ACOG | K2: 766522/077943 | L2: PEQ-15 | M2: 239025 | N2: PVS-14 | O2: 6542869 | AJ2: ASIP | AK2: 005532 | AT2: M952 LIGHT | AU2: A020163
A3: SCT | B3: Z | C3: M4 | D3: 2 | F3: UNASSIGNED | H3: M4 | I3: W011008 | L3: PEQ-15 | M3: 439044 | N3: PVS-14 | AJ3: MBITR | AK3: 536226 | AT3: M952 LIGHT | AU3: A264614
A4: SCT | B4: Y | C4: M4 | D4: 3 | E4: SPC | F4: TURBITT | G4: CODY | H4: M4 | I4: W011050 | J4: ACOG | K4: 766546/076556 | L4: PEQ-15 | M4: 445661 | N4: PVS-14 | O4: 6517939 | Q4: M320 | AT4: M952 LIGHT | AU4: A316668
A5: SCT | B5: x | C5: M4 | D5: 4 | E5: SGT | F5: CANIDA | G5: CODY | H5: M4 | I5: W011072 | J5: ACOG | K5: 518629 | L5: PEQ-15 | M5: 443052 | N5: PVS-14 | O5: 74106814 | AJ5: ASIP | AK5: 32675 | AL5: 150 | AM5: 008787 | AT5: M952 LIGHT | AU5: A316675
A6: SCT | B6: x | C6: M4 | D6: 5 | E6: SSG | F6: PEREZ | G6: JUAN | H6: M4 | I6: W011097 | J6: ACOG | K6: 766534/076850 | L6: PEQ-15A | M6: 00056091 | N6: PVS-14 | O6: 6541701 | AT6: M952 LIGHT | AU6: A316676
A7: SCT | B7: x | C7: M4 | D7: 6 | E7: SPC | F7: BEASLEY | G7: WADE | H7: M4 | I7: W011609 | J7: ACOG | K7: 518610 | L7: PEQ-15 | M7: 239339 | N7: PVS-14 | O7: A3281 | AJ7: ASIP | AK7: 003029 | AL7: 150 | AM7: 003391 | AT7: M952 LIGHT | AU7: A316684
A8: SCT | B8: x | C8: M4 | D8: 7 | E8: CPL | F8: JACKSON | G8: KHALIB | H8: M4 | I8: W011612 | J8: TMR | K8: 278678W | L8: PEQ-15A | M8: 00056399 | N8: PVS-14 | O8: 74106810 | AT8: M952 LIGHT | AU8: A317428
A9: SCT | B9: x | C9: M4 | D9: 8 | E9: CPL | F9: HOLLIS | G9: SCOTT | H9: M4 | I9: W011613 | J9: ACOG | K9: 766525/077896 | L9: PEQ-15 | M9: 261032 | N9: PVS-14 | O9: 6543961 | AT9: M952 LIGHT | AU9: A317445
A10: MED | B10: x | C10: M4 | D10: 9 | E10: PFC | F10: BERMUDEZ | G10: PETER | H10: M4 | I10: W011619 | J10: M68 | K10: W2108897 | L10: PEQ-15 | M10: 239399 | N10: PVS-14 | O10: 585 | AT10: M952 LIGHT | AU10: A317449
A11: SCT | B11: x | C11: M4 | D11: 10 | E11: SGT | F11: GIBSON | G11: JAMES | H11: M4 | I11: W011683 | J11: ACOG | K11: 525138 | L11: PEQ-15 | M11: 439351 | N11: PVS-14 | O11: 6517929 | Q11: PED-7 | R11: 754 | AT11: M952 LIGHT | AU11: A317556
A12: SCT | B12: x | C12: M4 | D12: 11 | E12: PFC | F12: GILLIARD | G12: BRYSON | H12: M4 | I12: W689754 | J12: ACOG | K12: 518611 | L12: PEQ-15 | M12: 398407 | N12: PVS-14 | O12: 6518157 | Q12: M320 | R12: 254-002140 | AT12: M952 LIGHT | AU12: A317564
A13: SCT | B13: Z | C13: M4 | D13: 12 | F13: UNASSIGNED | H13: M4 | I13: W011689 | J13: ACOG | K13: 518624 | L13: PEQ-15A | M13: 00041967 | N13: PVS-14 | O13: 6542866 | Q13: PAS-13D | R13: 210785 | S13: M2010 | T13: RR14022C | U13: HDMR | V13: 372065Y | W13: PEQ-15 | X13: 278401 | Y13: SUPPRESSOR | Z13: 02516 | AV13: M952 LIGHT | AW13: A317818
A14: SCT | B14: Z | C14: M4 | D14: 13 | F14: UNASSIGNED | H14: M4 | I14: W011694 | L14: PEQ-15A | M14: 00056099 | N14: PVS-14 | AT14: M952 LIGHT | AU14: A317828
A15: SCT | B15: x | C15: M4 | D15: 14 | E15: PFC | F15: CORREA | G15: JUSTIN | H15: M4 | I15: W011699 | J15: ACOG | K15: 518628 | L15: PEQ-15 | M15: 260892 | N15: PVS-14 | O15: 74106803 | AT15: M952 LIGHT | AU15: A317844
A16: SCT | B16: x | C16: M4 | D16: 15 | E16: PFC | F16: HAIRSTON | G16: JUSTIN | H16: M4 | I16: W011753 | J16: ACOG | K16: 524557 | L16: PEQ-15 | M16: 260894 | N16: PVS14 | O16: 6542877 | Q16: PAS-13D | R16: 210851 | AJ16: ASIP | AK16: 25805 | AL16: 150 | AM16: 2738 | AT16: M952 LIGHT | AU16: A317849
A17: SCT | B17: x | C17: M4 | D17: 16 | E17: PFC | F17: NEWCOMB | G17: JOSEPH | H17: M4 | I17: W011755 | J17: ACOG | K17: 552649 | L17: PEQ-15 | M17: 260900 | N17: PVS-14 | O17: 6518409 | AT17: M952 LIGHT | AU17: A317851
A18: SCT | B18: x | C18: M4 | D18: 17 | E18: SGT | F18: BARNES | G18: TYLER | H18: M4 | I18: W011764 | J18: ACOG | K18: 524639 | L18: PEQ-15 | M18: 260897 | N18: PVS-14 | O18: 6543972 | AJ18: MBITR | AK18: 536226 | AT18: M952 LIGHT | AU18: A317852
A19: SCT | B19: x | C19: M4 | D19: 18 | E19: SPC | F19: WRIGHT | G19: JACOB | H19: M4 | I19: W011784 | J19: ACOG | K19: 766536/077723 | L19: PEQ-15A | M19: 00056104 | N19: PVS-14 | O19: 6518627 | Q19: PAS-13D | R19: 207594 | S19: M320 | T19: 254-002135 | AV19: M952 LIGHT | AW19: A318092
A20: SCT | B20: x | C20: M4 | D20: 19 | E20: CPT | F20: ZBINDEN | G20: TEMPORARILY | H20: M4 | I20: W011822 | J20: ACOG | K20: 525136 | L20: PEQ-15 | M20: 260899 | O20: 6517971 | P20: USUALLY REACH SCOUTS | Q20: M110 | R20: 05344 | S20: HDMR | T20: AU37067 | U20: PEQ-15 | V20: 445574 | W20: SUPPRESSOR | X20: S075862 | AT20: M952 LIGHT | AU20: A318096
A21: SCT | B21: x | C21: M4 | D21: 20 | E21: SPC | F21: HOMAN | G21: GAVIN | H21: M4 | I21: W011891 | J21: ACOG | K21: 525143 | L21: PEQ-15 | M21: 239310 | N21: PVS-14 | O21: 6517951 | AT21: M952 LIGHT | AU21: A318100
A22: MED | B22: x | C22: M4 | D22: 21 | E22: SPC | F22: CYR | G22: SCHYLAR | H22: M4 | I22: W011892 | J22: CCO | K22: W2487337 | L22: PEQ-15 | M22: 260898 | N22: PVS-14 | O22: 6526515 | AJ22: MBITR | AK22: 23660 | AT22: M952 LIGHT | AU22: A318101
A23: SCT | B23: x | C23: M4 | D23: 22 | E23: PFC | F23: FISCHL | G23: RILEY | H23: M4 | I23: W011899 | J23: ACOG | K23: 518625 | L23: PEQ-15 | M23: 261040 | N23: PVS-14 | O23: 6543973 | AJ23: SKL | AK23: 237890 | AL23: 150 | AM23: 5101 | AN23: DAGR | AO23: 34543 | AT23: M952 LIGHT | AU23: A318252
A24: SCT | B24: x | C24: M4 | D24: 23 | E24: SPC | F24: CRAIG | G24: CHARLES | H24: M4 | I24: W011907 | J24: ACOG | K24: 552643 | L24: PEQ-15 | M24: 261041 | N24: PVS-14 | O24: 6542874 | Q24: PAS-13D | R24: 210832 | AT24: M952 LIGHT | AU24: A318478
A25: SCT | B25: x | C25: M4 | D25: 24 | E25: SGT | F25: LANDRUM | G25: CHRISTOPHER | H25: M4 | I25: W011921 | J25: TMR | K25: 286506W | L25: PEQ-15 | M25: 443186 | N25: PVS-14 | O25: 6542855 | Q25: PED-7 | R25: 1519 | S25: M110 | T25: 05341 | U25: TMR | V25: 376707X | W25: PEQ-15 | X25: 439381 | Y25: SUPPRESSOR | Z25: S075891 | AV25: M952 LIGHT | AW25: A318523
A26: SCT | B26: x | C26: M4 | D26: 25 | E26: SPC | F26: BANCROFT | G26: GRANGER | H26: M4 | I26: W012087 | J26: ACOG | K26: 525145 | L26: PEQ-15 | M26: 261048 | N26: PVS-14 | O26: 74106860 | Q26: M320 | R26: 254-002140 | AT26: M952 LIGHT | AU26: A318525
A27: SCT | B27: Y | C27: M4 | D27: 26 | E27: SGT | F27: SPENCER | G27: PHILIP | H27: M4 | I27: W012101 | J27: ACOG | K27: 584627 | L27: PEQ-15 | M27: 261046 | N27: PVS-14 | O27: 6518489 | Q27: PAS-13D | R27: 211718 | AT27: M952 LIGHT | AU27: A318553
A28: SCT | B28: x | C28: M4 | D28: 27 | E28: PFC | F28: LELAND | G28: TEMPORARILY | H28: M4 | I28: W012104 | J28: ACOG | K28: 652036 | L28: PEQ-15 | M28: 239026 | N28: PVS-14 | O28: 6542858 | P28: USUALLY JOSKOWITZ | Q28: PAS-13D | R28: 211725 | AT28: M952 LIGHT | AU28: A318600
A29: SCT | B29: x | C29: M4 | D29: 28 | E29: SGT | F29: LAIRD | G29: TY | H29: M4 | I29: W012112 | J29: ACOG | K29: 525147 | L29: PEQ-15 | M29: 261049 | N29: PSQ-20B | O29: 4192 | Q29: PAS-13D | R29: 210763 | AT29: M952 LIGHT | AU29: A318611
A30: HQ | B30: x | C30: M4 | D30: 29 | E30: SPC | F30: STROEVE | G30: ETHAN | H30: M4 | I30: W012116 | J30: ACOG | K30: 584649 | L30: PEQ-15 | M30: 261086 | N30: PVS-14 | O30: 552 | AX30: M952 LIGHT | AY30: A318624
A31: SCT | B31: x | C31: M4 | D31: 30 | E31: SGT | F31: CLINE | G31: BENJAMIN | H31: M4 | I31: W012131 | J31: ACOG | K31: 525164 | L31: PEQ-15 | M31: 261517 | N31: PVS-14 | O31: 6533513 | Q31: PAS-13D | R31: 210760 | S31: PED-7 | T31: 2146 | U31: M110 | V31: 05347 | W31: HDMR | X31: ET35215H | Y31: PEQ-15 | Z31: 438790 | AA31: SUPPRESSOR | AB31: S075839 | AJ31: MBITR | AK31: 519249 | AT31: M952 LIGHT | AU31: A318653
A32: SCT | B32: x | C32: M4 | D32: 31 | E32: SFC | F32: O’SHIELDS | G32: JEREMY | H32: M4 | I32: W012135 | J32: ACOG | K32: 766535/076851 | L32: PEQ-15 | M32: 395410 | N32: PVS-14 | O32: 74106855 | AT32: M952 LIGHT | AU32: A318659
A33: MRT | B33: x | C33: M4 | D33: 32 | E33: 1LT | F33: BRYANT | G33: CODY | H33: M4 | I33: W012146 | J33: EO TECH | K33: A0488953 | L33: PEQ-15 | M33: 278443 | N33: PVS-14 | O33: 5045 | AT33: M952 LIGHT | AU33: A318660
A34: MRT | B34: x | C34: M4 | D34: 33 | E34: SSG | F34: FOUNTAIN | G34: RYAN | H34: M4 | I34: W012167 | J34: ACOG | K34: 766554/077808 | L34: PEQ-15 | M34: 261722 | N34: PVS-14 | O34: 6542865 | AT34: M952 LIGHT | AU34: A318666
A35: MRT | B35: x | C35: M4 | D35: 34 | E35: PV2 | F35: RUPPAL | G35: HUNTER | H35: M4 | I35: W012186 | J35: M68 | K35: W2490408 | L35: PEQ-15 | M35: 439303 | N35: PVS-14 | O35: 74106843 | AT35: M952 LIGHT | AU35: A318669
A36: MRT | B36: x | C36: M4 | D36: 35 | E36: PFC | F36: ATKINSON | G36: PRESCOTT | H36: M4 | I36: W012208 | J36: M68 | K36: W2488301 | L36: PEQ-15 | M36: 261784 | N36: PVS-14 | O36: 74106841 | AT36: M952 LIGHT | AU36: A318671
A37: MRT | B37: x | C37: M4 | D37: 36 | E37: PFC | F37: WALL | G37: JOSEPH | H37: M4 | I37: W012224 | J37: M68 | K37: W2490411 | L37: PEQ-15 | M37: 261793 | N37: PVS-14 | O37: 74106820 | AT37: M952 LIGHT | AU37: A318672
A38: MRT | B38: x | C38: M4 | D38: 37 | E38: PFC | F38: AVALOS | G38: JACOB | H38: M4 | I38: W012232 | J38: M68 | K38: W2488308 | L38: PEQ-15 | M38: 261795 | N38: PVS-14 | O38: 6541109 | AT38: M952 LIGHT | AU38: A318673
A39: MRT | B39: x | C39: M4 | D39: 38 | E39: PFC | F39: MORA | G39: TEMPORARILY | H39: M4 | I39: W012237 | J39: M68 | K39: W2487338 | L39: PEQ-15 | M39: 261896 | N39: PVS-14 | O39: 74106807 | P39: USUALLY THOMPSON / NVGS NEEDS NEW DATA PLATE | Q39: PAS-13E(V)3 | R39: 873916 | AT39: M952 LIGHT | AU39: A318674
A40: MRT | B40: x | C40: M4 | D40: 39 | E40: SPC | F40: PAYNE | G40: ERRIN | H40: M4 | I40: W012267 | J40: M68 | K40: W2490399 | L40: PEQ-15 | M40: 278310 | N40: PVS-14 | O40: 74106846 | AT40: M952 LIGHT | AU40: A318839
...

Sheet REAR M4s
A1: SECTION | B1: IDENTIFIER | C1: WPN | D1: STOCK NO. | E1: RANK | F1: LASTNAME | G1: FIRSTNAME | I1: PRIMARY WEAPON | J1: SERIAL | K1: OPTIC | L1: SERIAL | M1: PEQ | N1: SERIAL | O1: NODS | P1: SERIAL
A2: SCT | C2: M4 | D2: 2 | F2: UNASSIGNED | I2: M4 | J2: W011008 | M2: PEQ-15 | N2: 439044 | O2: PVS-14
A3: SCT | C3: M4 | D3: 13 | F3: UNASSIGNED | I3: M4 | J3: W011694 | M3: PEQ-15A | N3: 00056099 | O3: PVS-14
A4: S3 | C4: M4 | D4: 86 | E4: SSG | F4: BENNETT | G4: MICHAEL | H4: BENNETT, MICHAEL | I4: M4 | J4: W047750 | K4: M68 | L4: W2487335 | M4: PEQ-15 | N4: 439049 | O4: PVS-14 | P4: 6542877
A5: S3 | C5: M4 | D5: 90 | F5: UNASSIGNED | I5: M4 | J5: W047789 | K5: M68 | L5: 1013226 | M5: PEQ-15 | N5: 439308 | O5: PVS-14
A6: S4 | C6: M4 | D6: 95 | E6: SGT | F6: POKORNY | G6: BRADLEY | H6: POKORNY, BRADLEY | I6: M4 | J6: W047805 | K6: M68 | L6: W2488315 | M6: PEQ-15 | N6: 439512 | O6: PVS-14 | P6: 6542852
A7: S6 | C7: M4 | D7: 100 | F7: UNASSIGNED | H7: UNASSIGNED, | I7: M4 | J7: W047829 | K7: M68 | L7: W2487343 | M7: PEQ-15 | N7: 443013 | O7: PVS-14 | P7: 74106805
A8: MED | C8: M9 | D8: 107 | F8: UNASSIGNED | I8: M4 | J8: W047905 | K8: EOTECH | L8: 117632 | M8: PEQ-15 | N8: 443193 | O8: PVS-14
A9: MED | C9: M4 | D9: 108 | F9: UNASSIGNED | I9: M4 | J9: W047907 | K9: M68 | M9: PEQ-15 | O9: PVS-14
A10: MED | C10: M4 | D10: 113 | E10: PFC | F10: SMITH | G10: GEORGIA | I10: M4 | J10: W048005 | K10: M68 | L10: W2053863 | M10: PEQ-15 | O10: PVS-14
A11: MED | C11: M4 | D11: 124 | E11: PFC | F11: CYR | G11: SCHYLAR | I11: M4 | J11: W048281 | K11: M68 | L11: 982896 | O11: PVS-14
A12: MED | C12: M4 | D12: 128 | F12: UNASSIGNED | I12: M4 | J12: W048716 | K12: M68 | L12: W2488306 | O12: PVS-14
A13: MED | C13: M4 | D13: 129 | E13: SPC | F13: KOO | G13: INHOI | I13: M4 | J13: W048718 | K13: M68 | L13: K2499422 | O13: PVS-14
A14: MED | C14: M4 | D14: 131 | E14: SGT | F14: ROSS | G14: SAMUEL | I14: M4 | J14: W048730 | K14: M68 | L14: 1013264 | O14: PVS-14
A15: MED | C15: M4 | D15: 132 | F15: UNASSIGNED | I15: M4 | J15: W582105 | K15: M68 | L15: W2487348 | O15: PVS-14
A16: S3 | C16: M9 | D16: 134 | E16: SFC | F16: MARTINEZ | G16: DANIEL | I16: M4 | J16: W689737 | K16: M68 | M16: PEQ-15 | N16: 439518 | O16: PVS-14
A17: S3 | C17: M4 | D17: 136 | E17: 2LT | F17: LARRABEE | G17: COLIN | I17: M4 | J17: W048325 | K17: M68 | L17: W2487333 | M17: PEQ-15A | N17: 00014694 | O17: PVS-14
A18: S3 | C18: M4 | D18: 151 | F18: UNASSIGNED | I18: M4 | J18: W690523 | K18: M68 | L18: W2490410 | O18: PVS-14
D19: 152 | F19: UNASSIGNED | I19: M4 | J19: W012488 | O19: PVS-14
D20: 153 | F20: UNASSIGNED | I20: M4 | J20: W012391 | O20: PVS-14
D21: 154 | F21: UNASSIGNED | I21: M4 | J21: W048042 | O21: PVS-14
D22: 155 | F22: UNASSIGNED | I22: M4 | J22: W011686 | O22: PVS-14
I23: M4 | J23: W047962
I24: M4 | J24: W0007136
I25: M4 | J25: W0008840
I26: M4 | J26: W048711
I27: M4 | J27: W0008211
I28: M4 | J28: W708517
M29: PEQ-15A | N29: 00049949
M30: PEQ-15A | N30: 00041961

Sheet Shermett
A1: POS | B1: LN | C1: NAME | D1: RACK | E1: M4 | F1: M9 | G1: M240 | H1: M320 | I1: M145 | J1: M68 | K1: ACOG | L1: EOTECH | M1: TMR | N1: PAS-13E(V)3 | O1: PAS-13G | P1: PEQ-15 | Q1: PEQ-15A | R1: PVS-14 | S1: PSQ-20B
C2: 1LT MILLIGAN, ROBERT | D2: 1 | E2: W010240 | K2: 766522/077943 | P2: 239025 | R2: 6542869
C3: SPC TURBITT, CODY | D3: 3 | E3: W011050 | H3: 254-002135 | K3: 766546/076556 | P3: 445661 | R3: 6517939
C4: SGT CANIDA, CODY | D4: 4 | E4: W011072 | K4: 518629 | P4: 443052 | R4: 74106814
C5: SSG PEREZ, JUAN | D5: 5 | E5: W011097 | K5: 766534/076850 | Q5: 00056091 | R5: 6541701
C6: SPC BEASLEY, WADE | D6: 6 | E6: W011609 | K6: 518610 | P6: 239339 | R6: 6518627
C7: CPL JACKSON, KHALIB | D7: 7 | E7: W011612 | F7: 1323516 | M7: 278678W | Q7: 00056399 | R7: A3281
C8: CPL HOLLIS, SCOTT | D8: 8 | E8: W011613 | K8: 766525/077896 | P8: 239353 | R8: 6543961
C9: PFC BERMUDEZ, PETER | D9: 9 | E9: W011619 | J9: W2108897 | P9: 239399 | R9: 585
C10: SGT GIBSON, JAMES | D10: 10 | E10: W011683 | F10: 1196962 | K10: 525138 | P10: 439351 | R10: 6517929
C11: PFC GILLIARD, BRYSON | D11: 11 | E11: W689754 | K11: 518611 | P11: 398407 | R11: 6518157
C12: SPC STROEVE, ETHAN | D12: 12 | E12: W011689 | F12: 1495041 | K12: 518624 | Q12: 00041907 | R12: 6542866
C13: PFC CORREA, JUSTIN | D13: 14 | E13: W011699 | K13: 518628 | P13: 260892 | R13: 74106803
C14: PFC HAIRSTON, JUSTIN | D14: 15 | E14: W011753 | K14: 524557 | P14: 260894 | S14: 4072
C15: PFC NEWCOMB, JOSEPH | D15: 16 | E15: W011755 | K15: 552649 | P15: 260900 | R15: 6518409
C16: SGT BARNES, TYLER | D16: 17 | E16: W011764 | K16: 524639 | P16: 260897 | R16: 6543972
C17: SPC WRIGHT, JACOB | D17: 18 | E17: W011784 | H17: 254-002157 | K17: 766536/077723 | P17: 260898 | R17: 6517961
C18: SPC REACH, JACOB | D18: 19 | E18: W011822 | F18: 1495284 | K18: 525136 | P18: 260899 | R18: 6542858
C19: SPC HOMAN, GAVIN | D19: 20 | E19: W011891 | K19: 525143 | P19: 239310 | R19: 6517951
C20: SGT BARR, PATRICK | D20: 21 | E20: W011892 | K20: 533324 | P20: 261032 | R20: 6517903
C21: PFC FISCHL, RILEY | D21: 22 | E21: W011899 | K21: 518625 | P21: 261040 | R21: 6543973
C22: SPC CRAIG, CHARLES | D22: 23 | E22: W011907 | K22: 552643 | P22: 261041 | R22: 6542874
C23: SGT LANDRUM, CHRISTOPHER | D23: 24 | E23: W011921 | F23: 1196959 | M23: 286506W | P23: 443186 | R23: 6542855
C24: SPC BANCROFT, GRANGER | D24: 25 | E24: W012087 | H24: 254-002140 | K24: 525145 | P24: 261048 | R24: 74106860
C25: SGT SPENCER, PHILIP | D25: 26 | E25: W012101 | K25: 584627 | P25: 261046 | R25: 6518489
C26: PFC JOSKOWITZ, ETHAN | D26: 27 | E26: W012104 | K26: 652036 | P26: 239026 | R26: 6518623
C27: SGT LAIRD, TY | D27: 28 | E27: W012112 | K27: 525147 | P27: 261049 | S27: 4192
C28: PFC HOWARD, CAMERON | D28: 29 | E28: W012116 | K28: 584649 | P28: 261086 | R28: 6543967
C29: SGT CLINE, BENJAMIN | D29: 30 | E29: W012131 | F29: 1196972 | K29: 525164 | P29: 261517 | R29: 6533513
C30: SFC O’SHIELDS, JEREMY | D30: 31 | E30: W012135 | K30: 766535/076851 | P30: 395410 | R30: 74106855
C31: 1LT BRYANT, CODY | D31: 32 | E31: W012146 | L31: A0488953 | P31: 278443 | R31: 5045
C32: SSG FOUNTAIN, RYAN | D32: 33 | E32: W012167 | K32: 766554/077808 | P32: 261722 | R32: 6542865
C33: PV2 RUPPAL, HUNTER | D33: 34 | E33: W012186 | J33: W2490408 | P33: 439303 | R33: 74106843
C34: PFC ATKINSON, PRESCOTT | D34: 35 | E34: W012208 | J34: W2488301 | P34: 261784 | R34: 74106841
C35: PFC WALL, JOSEPH | D35: 36 | E35: W012224 | J35: W2490411 | P35: 261793 | R35: 74106820
C36: PFC AVALOS, JACOB | D36: 37 | E36: W012232 | J36: W2488308 | P36: 261795 | R36: 6541109
C37: SPC THOMPSON, JOSEPH | D37: 38 | E37: W012237 | J37: W2487338 | N37: 873916 | P37: 261896 | R37: 74106807
C38: SPC PAYNE, ERRIN | D38: 39 | E38: W012267 | J38: W2490399 | P38: 278310 | R38: 74106846
C39: SGT ALLEN, AUSTIN | D39: 40 | E39: W012286 | J39: W2488319 | O39: 704028 | P39: 278313 | R39: 6507750
C40: SGT BATISTO, ANGELITO | D40: 41 | E40: W012293 | J40: W2490407 | P40: 278315 | R40: 6517922
...

Sheet Rhino Mount Shortage
B1: RHINO MOUNTS NEEDED | D1: REMAINING | E1: 21
A2: HQ
A3: CMD | B3: 2
A4: SCT
A5: MRT | B5: 2
A6: MED
A7: S1 | B7: 3
A8: S2
A9: S3 | B9: 8
A10: S4 | B10: 4
A11: S6 | B11: 4
A12: TOTAL | B12: =SUM(B2:B11) -> 23

Sheet MAL KEY
A3: GENERIC NOMENCLATURE | B3: LIN | C3: SUB | D3: NSN NOMENCLATURE | E3: WHAT JOE CALLS IT | F3: NSN | G3: COST | H3: TOTAL | I3: OH
A4: [PFED] | C4: C05011 | D4: COMPUTER SYSTEM, DIG | E4: PFED | F4: 7010015389663 | G4: 3442 | H4: 13768 | I4: 4
A5: AIMING CIRCLE | B5: A22496 | D5: AIMING CIRCLE M2A2 | E5: M2A2 | F5: 6675010670687 | G5: 13896 | H5: 55584 | I5: 4
A6: BATTLEFIELD ANTI-INTRUSION SYS: AN/PRS-9 | B6: B57077 | D6: BATTLEFIELD ANTI-IN | E6: BIAS | F6: 6350015932817 | G6: 90 | H6: 1350 | I6: 15
A7: BAYONET MULTIPUROSE SYSTEM: XM9 | B7: B49004 | D7: BAYONET MULTI SYS M9 | E7: BAYONET (M9) | F7: 1095012271739 | G7: 10000 | H7: 30000 | I7: 3
A8: BINOCULAR: M24 | B8: B67839 | D8: BINO W/O RET M24 | E8: M24 | F8: 1240014123128 | G8: 138 | H8: 1380 | I8: 10
A9: BINOCULAR: M24 | B9: B67839 | D9: M24 BINOCULAR | E9: M24 | F9: 1240014993547 | G9: 3725 | H9: 7450 | I9: 2
A10: BINOCULAR: M25 | B10: B67907 | D10: BINO M25 | E10: M25 | F10: 1240014107418 | G10: 58 | H10: 10788 | I10: 186
A11: BOINO: MOD CONSTR. MIL SCALE RET 7X50 | B11: B67766 | D11: BINO MOD CON M22 | E11: M22 | F11: 1240012075787 | G11: 32640 | H11: 97920 | I11: 3
A12: BOINO: MOD CONSTR. MIL SCALE RET 7X50 | B12: B67766 | D12: BINO MOD CON M22 | E12: M22 | F12: 1240013611318 | G12: 635 | H12: 635 | I12: 1
A13: BORESIGHTING EQUIP WPN: SMALL ARMS M30 | B13: B60351 | D13: BORESIGHT EQUIP M30 | E13: BORESIGHT | F13: 5860013947781 | G13: 342 | H13: 7524 | I13: 22
A14: COLLIMATOR, BORESIGHT | B14: FA5506 | D14: COLLIMATOR BORESIGH-(SU-93A) | E14: BORESIGHT | F14: 5855011096433 | G14: SAME | H14: 8550 | I14: 25
A15: COMMAND LAUNCH UNIT: (JAVELIN) | B15: C60750 | D15: COMMAND LAUNCH UNIT | E15: CLU | F15: 1430015328900 | G15: 290 | H15: 1740 | I15: 6
A16: COMPUTER SET BALLISTICS: MORTAR M23 | B16: C60294 | D16: COMPUTER SET BALLIS | E16: M23 | F16: 1220011196049 | G16: 355 | H16: 4260 | I16: 12
A17: COMPUTER SYSTEM DIGITAL: AN/PSG-10 (V) | B17: C05011 | D17: COMPUTER SYSTEM, DIG | E17: PFED | F17: 7010014919156 | G17: 6120 | H17: 24480 | I17: 4
A18: COMPUTER, PERSONAL WORKSTATION | B18: 70209N | D18: COMPUTER, DIGITAL -(LHMBC, M32) | E18: LHMBC | F18: 7021015553403 | G18: 28694 | H18: 114776 | I18: 4
A19: COMTER SYS DIG: AN/PSG-14(V)1 LFED | B19: C04819 | D19: COPTR SY DIG: AN/PSG | E19: LFED | F19: 7010015608481 | G19: 31161 | H19: 249288 | I19: 8
A20: CONVERSION KIT | B20: ZA0507 | D20: CONVERSION KIT: 5305655 GENERAL DYNAMICS | F20: 100501C055967 | G20: 8114 | H20: 121710 | I20: 15
B21: ZA0507 | F21: 1005991322615 | G21: 9000 | H21: 45000 | I21: 5
A22: DEMOLITION SET EXPLOSIVE: INIATING … | B22: F91490 | D22: DEMO SET EXPLO ELEC | E22: DEMO | F22: 1375000473750 | G22: 133063 | H22: 798378 | I22: 6
A23: ELECTRONIC TEST SET SET: TS-4348/UV | B23: E03826 | D23: TEST SET TS-4348/UV | E23: TEST SET | F23: 6625013239584 | G23: 645 | H23: 2480 | I23: 4
A24: FLASHLIGHT | B24: FE3077 | D24: FLASHLIGHT: WPN MT M952 KIT01 SUREFIRE | E24: TAC-LIGHT | F24: 623001F003915 | G24: 1900 | H24: 1900 | I24: 1
B25: ZA9568 | C25: 94117N | D25: HOLSTER, PISTOL [ACU] | E25: ACU HOLSTER | F25: 1095015411514 | G25: 25000 | H25: 25000 | I25: 1
A26: HVY. WPN. THERMAL SIGHT: AN/PAS-13(V)3 | B26: S90603 | D26: SI THE AN/PAS-13B(V)3 | F26: 5855014643151 | G26: 4829 | H26: 19316 | I26: 4
B27: S90603 | D27: SI THE AN/PAS-13C(V)3 | F27: 5855015237715 | G27: 18672 | H27: 18672 | I27: 1
B28: S90603 | D28: SI THE AN/PAS-13D(V)3 | F28: 5855015244314 | G28: 8698 | H28: 17396 | I28: 2
A29: ILLUMIN. INTEGRATED: S. ARMS STORM MLRF | B29: J68653 | D29: ILL INT SMALL ARM MLRF | F29: 5855015351905 | G29: 1421 | H29: 7105 | I29: 5
A30: ILLUMINATOR INTEGRATED: SM. ARMS STORM MLRF | B30: J68653 | D30: ILLUMINATOR INTEGRATE | F30: 5855015775946 | G30: 72 | H30: 7776 | I30: 108
A31: ILLUMINATOR, INFRARED | B31: FA5554 | D31: ILLUMINATOR: D424-100 IZLID | E31: IZLID | F31: 585501C057659 | G31: 258 | H31: 15222 | I31: 59
B32: FA5554 | D32: ILLUMINATOR, INFRARED-(M646) | E32: RAPTOR | F32: 5855014652170 | G32: 298080 | H32: 298080 | I32: 1
B33: JO3261 | D33: ILLUMINATOR INTEGRA | F33: 5855015356166 | G33: 529 | H33: 5819 | I33: 11
B34: JO3261 | D34: ILLUMIN INFRARED | F34: 5855015345931 | G34: 6539 | H34: 65390 | I34: 10
A35: INTERFACE UNIT COMM EQPMT | B35: FA9527 | D35: INTERFACE UNIT, DATA [LHMBC COMPONENT] | E35: LHMBC POCKET PC | F35: 5895015216922 | G35: 884 | H35: 83096 | I35: 94
A36: LASER POINTER | B36: WB204V | F36: 752001C075571 | G36: 895 | H36: 28640 | I36: 32
A37: LAUNCHER: GRENADE | B37: L69012 | C37: L69080 | D37: LAUNCHER, GRENADE [320] | E37: 320 | F37: 1010015572542 | G37: 15971 | H37: 47913 | I37: 3
A38: LIGHT TACTICAL | B38: FE404E | D38: LIGHT TACTICAL…SUREFIRE | E38: TAC-LIGHT | F38: 624001C064018 | G38: 3500 | H38: 28000 | I38: 8
A39: LIGHTING KIT: MOTION DETECTOR (LKMD) AN/GAR-2 | B39: L02015 | D39: LIGHTING KIT MOTION | F39: 6210015376769 | G39: 3413 | H39: 51195 | I39: 15
A40: MACH GUN GRENADE 40MM: MK19 MOD III | B40: M92362 | D40: MACH GUN 40MM: MK19 | F40: 1010014909697 | G40: 121855 | H40: 487420 | I40: 4
A41: MACHINE GUN: CALIBER 50 | B41: M39331 | D41: MACHINE GUN CALIBER | E41: .50cal | F41: 1005015111250 | G41: 550 | I41: 20
A42: MED. WPN. THERMAL SIGHT: AN/PAS-13(V)2 | B42: S90535 | D42: SI THE AN/PAS-13B(V)2 | F42: 5855014643152 | G42: 1738 | H42: 1738 | I42: 1
...

Sheet NON-AA&E
A2: NON AA&E
A3: IDENTIFIER | B3: ITEM | C3: DESCRIPTION | D3: LIN | E3: HAND RECEIPT | F3: UL | G3: SII | H3: PB | I3: NSN | J3: QTY | N3: $$ea | O3: total
B4: M3 TRIPOD | C4: .50 CAL/MK19 TRIPOD | D4: M75577 | E4: MT TPD MG CAL .50 M3 | F4: 6,7 | H4: 19 | I4: 1005003229716 | J4: 4 | N4: 757 | O4: 3028
B5: BUSHNELL ELITE 1500 | C5: 320 RANGE FINDER | D5: L69012 | E5: M320A1 BII | F5: NA | G5: NA | I5: N/A | J5: 15
B6: DAGRS (V1) | C6: GPS | D6: N96248 | E6: NAV SET SAT AN/PSN-13 | F6: P.9 | G6: P.13 | I6: 5825015168038 | J6: 1
B7: DAGRS (V2) | C7: GPS | D7: N96248 | E7: NAVIGATION SET, SATE | F7: P.9 | G7: P.14 | I7: 5825015264783 | J7: 83
B8: DATA INTERFACE (LHMBC) | C8: INTERFACE UNIT | D8: FA9527 | E8: INTERFACE UNIT, DATA | F8: P.3 | G8: NA | I8: 5895015216922 | J8: 4
B9: DEMO SET | C9: DEMO SET: EXPLOSIVE | D9: F91490 | E9: DEMO SET EXPLO ELEC | F9: P.2 | G9: NA | I9: 1375000473750 | J9: 1
B10: GPA-1 | C10: LASER POINTER | D10: WB204V | E10: LASER POINTER: 736-GCP-1A NVEC | F10: P.17 | G10: NA | I10: 752001C075571 | J10: 3
B11: LATITUDE | D630 | C11: ARMS ROOM LAPTOP | D11: N/A | E11: LATITUDE | D630 | F11: NA | G11: NA | I11: N/A | J11: 1
B12: LIGHT TACTICAL | C12: FLASHLIGHT: TACTICAL | D12: FE3077 | E12: FLASHLIGHT: WEAPONS MOUNTED M952 KIT01 SUREFIRE | F12: P.3 | G12: NA | I12: 623001F003915 | J12: 108
B13: LIGHT TACTICAL | C13: FLASHLIGHT: TACTICAL | D13: FE404E | E13: LIGHT TACTICAL: 0BJZ8M951XM07 SUREFIRE | F13: P.3 | G13: NA | I13: 624001C064018 | J13: 59
B14: 249 TRIPOD | C14: TRIPOD: 249 | D14: M75964 | E14: MT TPD MG M122A1 | F14: 7 | G14: 8 | H14: 19 | I14: 1005014331617 | J14: 7 | N14: 512 | O14: 3584
B15: M23 | C15: COMPUTER (MTR) | D15: C60294 | E15: COMPUTER SET BALLIS | F15: P.2 | G15: NA | I15: 1220011196049 | J15: 5
B16: 249/240 TRIPOD | C16: TRIPOD: 249/240 | D16: M60256 | E16: MT MACH GUN M192 | F16: 6 | G16: 8 | H16: 19 | I16: 1005015030141 | J16: 12 | N16: 833 | O16: 9996
B17: M25 | C17: BINOCULAR | D17: B67907 | E17: BINOCULAR M25 | F17: P.2 | G17: NA | I17: 1240014107418 | J17: 4
B18: ACOG | C18: WPN MOUNTED SIGHT | D18: S45729 | E18: SIGHT BORE OPT M150 | F18: 14, 15 | G18: 23,24 | H18: 29,30 | I18: 1240015571897 | J18: 66 | N18: 1200 | O18: 84000
B19: PAS-13A (V2) | C19: **********PAS-13B V2********** | D19: S90535 | E19: SI THE AN/PAS-13A (V) 2 | F19: P.16 | G19: P.28 | I19: 5855014580210 | J19: 12
B20: PAS-13A (V3) | C20: ********** PAS-13B V3********* | D20: S90603 | E20: SI THE AN/PAS-13A (V) 3 | F20: P.16 | G20: P.28 | I20: 5855014580211 | J20: 2
B21: PEQ-15 (V1) | C21: GRAY | D21: J03261 | E21: ILLUMINATOR INTEGRA | F21: P.5 | G21: NA | I21: 5855015356166 | J21: 32
B22: PNEGL | C22: 320 LASER DESIGNATOR | D22: L69012 | E22: M320A1 BII | F22: NA | G22: NA | I22: N/A | J22: 15
B23: PSG-10V (PFED) | C23: COMPUTER SYSTEM | D23: Z00058 | E23: COMPUTER SYSTEM, DIG- (AN/PSG-10V) | F23: P.17 | G23: NA | I23: 7010014919156 | J23: 8
B24: PSG-11 (V1) | C24: COMPUTER SYSTEM (FST) | D24: D10788 | E24: COM SY AN/PSG-11 (V) 1 | F24: P.2 | G24: NA | I24: 7010014919157 | J24: 1
B25: PSQ-18A | C25: M203 SIGHT | D25: ZA1094 | E25: SIGHT, GRENADE LAUNC- (AN/PSQ-18A (M203) ) | F25: P.19 | G25: P.34 | I25: 1010015160953 | J25: 22
B26: QUADCON | C26: CONNEX | D26: WE1501 | E26: BOX SHIPPING QUADCON | F26: P.17 | G26: NA | I26: 8115014747089 | J26: 2
B27: SU-93A | C27: BORESIGHT | D27: FA5506 | E27: COLLIMATOR BORESIGH- (SU-93A) | F27: P.3 | G27: P.4 | I27: 5855011096433 | J27: 4
B28: TOOL KIT | C28: ARMS ROOM TOOL KIT | D28: MC802Z | E28: TOOL KIT,REPAIRMAN' | F28: P.7 | G28: NA | I28: 5180003577770 | J28: 1
B29: COMMAND LAUNCH UNIT | C29: JAVLIN AIMING DEVICE | D29: C60750 | E29: CMD LAUN UT JAV 2 BRD | F29: P.2 | G29: P.3 | I29: 1430014338025 | J29: 6
B30: ACOG | C30: WPN MOUNTED SIGHT | D30: S45729 | E30: SIGHT BORE OPT M150 | F30: 12 | G30: 20 | H30: 28 | I30: 1240015571897 | J30: 17 | N30: 1200 | O30: 16800
B31: ADAPTER RAIL | C31: RAIL SYSTEM FOR 5.56MM | D31: ZA0592 | E31: ADAPTER RAIL, WEAPON | F31: 17 | H31: 36 | I31: 1005014523527 | J31: 206 | N31: 74 | O31: 15244
B32: BALLISTIC COMPUTER | C32: MRT COMPUTER M23 | D32: C60294 | E32: COMPUTER SET BALLIS | F32: 2 | H32: 10 | I32: 1220011196049 | J32: 5 | N32: 9000 | O32: 45000
B33: BAYONET | C33: BAYONET | D33: B49004 | E33: BAYONET MULTI SYS M9 | F33: 1 | H33: 7 | I33: 1095012271739 | J33: 186 | N33: 58 | O33: 10788
B34: BIAS | C34: GROUND SENSOR | D34: B57077 | E34: BATTLEFIELD ANTI-IN | F34: 1 | H34: 7 | I34: 6350015932817 | J34: 3 | N34: 32640 | O34: 97920
B35: BORESIGHT | C35: ZERO LASER | D35: FA5506 | E35: COLLIMATOR BORESIGH- (SU-93A) | F35: 2 | G35: 4 | H35: 13 | I35: 5855011096433 | J35: 4 | N35: 4993 | O35: 19972
B36: CLU | C36: JAVLIN AIMING DEVICE | D36: C60750 | E36: COMMAND LAUNCH UNIT | F36: 2 | G36: 2 | H36: 10 | I36: 1430015328900 | J36: 6 | N36: 133063 | O36: 798378
B37: DAGR: AN/PSN13 | C37: GPS NAVIGATION | D37: N96248 | E37: NAVIGATION SET, SATE | F37: 9,10 | G37: 12,13 | H37: 22 | I37: 5825015264783 | J37: 85 | N37: 4598 | O37: 390830
B38: DAGR: AN/PSN13 | C38: GPS NAVIGATION | D38: N96248 | E38: NAV SET SAT AN/PSN-13 | F38: 9 | G38: 12 | H38: 21,22 | I38: 5825015168038 | J38: 1 | N38: 2832 | O38: 2832
B39: EOTECH | C39: WPN MOUNTED SIGHT | D39: GA405T | E39: SIGHT, HOLOGRAPHIC-(EOTECH 552.A65) | F39: 4 | G39: 4,5 | H39: 15 | I39: 1240014925264 | J39: 11 | N39: 407 | O39: 4477
B40: EUGS | C40: GROUND VIBRATION SENSOR | D40: FA102R | E40: UNATTENDED GROUND SENSOR SYSTEM | F40: 2 | H40: 12,13 | J40: 1 | N40: 25000
B41: GUN MOUNT: 50c/40MM | C41: GUN MOUNT | D41: M74823 | E41: MT MAC GUN 40MM MK93 | F41: 6 | G41: 8 | H41: 19 | I41: 1010013832757 | J41: 2 | N41: 1678 | O41: 3356
...

Sheet 2062
A1: HAND RECEIPT/ANNEX NUMBER | J1: FROM: | S1: TO: | U1: Section: | Z1: =#VALUE! -> #VALUE! | AB1: HAND RECEIPT | AE1: HAND RECEIPT/ANNEX NUMBER | AN1: FROM: | AW1: TO: | AY1: Section: | BD1: =#VALUE! -> #VALUE! | BF1: HAND RECEIPT | BI1: HAND RECEIPT/ANNEX NUMBER | BR1: FROM: | CA1: TO: | CC1: Section: | CH1: =MAL!A2 -> SCT | CJ1: HAND RECEIPT | CM1: HAND RECEIPT/ANNEX NUMBER | CV1: FROM: | DE1: TO: | DG1: Section: | DL1: =MAL!A3 -> SCT | DN1: HAND RECEIPT | DQ1: HAND RECEIPT/ANNEX NUMBER | DZ1: FROM: | EI1: TO: | EK1: Section: | EP1: =#VALUE! -> #VALUE! | ER1: HAND RECEIPT | EU1: HAND RECEIPT/ANNEX NUMBER | FD1: FROM: | FM1: TO: | FO1: Section: | FT1: MAL (V2)'!B | FV1: HAND RECEIPT | FY1: HAND RECEIPT/ANNEX NUMBER | GH1: FROM: | GQ1: TO: | GS1: Section: | GX1: MAL (V2)'!B | GZ1: HAND RECEIPT | HC1: HAND RECEIPT/ANNEX NUMBER | HL1: FROM: | HU1: TO: | HW1: Section: | IB1: =#VALUE! -> #VALUE! | ID1: HAND RECEIPT | IG1: HAND RECEIPT/ANNEX NUMBER | IP1: FROM: | IY1: TO: | JA1: Section: | JF1: =#VALUE! -> #VALUE! | JH1: HAND RECEIPT | JK1: HAND RECEIPT/ANNEX NUMBER | JT1: FROM: | KC1: TO: | KE1: Section: | KJ1: =MAL!HC2 -> 0 | KL1: HAND RECEIPT | KO1: HAND RECEIPT/ANNEX NUMBER | KX1: FROM: | LG1: TO: | LI1: Section: | LN1: =MAL!HC3 -> 0 | LP1: HAND RECEIPT | LS1: HAND RECEIPT/ANNEX NUMBER | MB1: FROM: | MK1: TO: | MM1: Section: | MR1: =#VALUE! -> #VALUE! | MT1: HAND RECEIPT | MW1: HAND RECEIPT/ANNEX NUMBER | NF1: FROM: | NO1: TO: | NQ1: Section: | NV1: MAL (V2)'!B | NX1: HAND RECEIPT | OA1: HAND RECEIPT/ANNEX NUMBER | OJ1: FROM: | OS1: TO: | OU1: Section: | OZ1: MAL (V2)'!B | PB1: HAND RECEIPT | PE1: HAND RECEIPT/ANNEX NUMBER | PN1: FROM: | PW1: TO: | PY1: Section: | QD1: =#VALUE! -> #VALUE! | QF1: HAND RECEIPT | QI1: HAND RECEIPT/ANNEX NUMBER | QR1: FROM: | RA1: TO: | RC1: Section: | RH1: =#VALUE! -> #VALUE! | RJ1: HAND RECEIPT | RM1: HAND RECEIPT/ANNEX NUMBER | RV1: FROM: | SE1: TO: | SG1: Section: | SL1: =MAL!PE2 -> 0 | SN1: HAND RECEIPT | SQ1: HAND RECEIPT/ANNEX NUMBER | SZ1: FROM: | TI1: TO: | TK1: Section: | TP1: =MAL!PE3 -> 0 | TR1: HAND RECEIPT | TU1: HAND RECEIPT/ANNEX NUMBER | UD1: FROM: | UM1: TO: | UO1: Section: | UT1: =#VALUE! -> #VALUE! | UV1: HAND RECEIPT | UY1: HAND RECEIPT/ANNEX NUMBER | VH1: FROM: | VQ1: TO: | VS1: Section: | VX1: MAL (V2)'!B | VZ1: HAND RECEIPT | WC1: HAND RECEIPT/ANNEX NUMBER | WL1: FROM: | WU1: TO: | WW1: Section: | XB1: MAL (V2)'!B | XD1: HAND RECEIPT | XG1: HAND RECEIPT/ANNEX NUMBER | XP1: FROM: | XY1: TO: | YA1: Section: | YF1: =#VALUE! -> #VALUE! | YH1: HAND RECEIPT | YK1: HAND RECEIPT/ANNEX NUMBER | YT1: FROM: | ZC1: TO: | ZE1: Section: | ZJ1: =#VALUE! -> #VALUE! | ZL1: HAND RECEIPT | ZO1: HAND RECEIPT/ANNEX NUMBER | ZX1: FROM: | AAG1: TO: | AAI1: Section: | AAN1: =MAL!XG2 -> 0 | AAP1: HAND RECEIPT | AAS1: HAND RECEIPT/ANNEX NUMBER | ABB1: FROM: | ABK1: TO: | ABM1: Section: | ABR1: =MAL!XG3 -> 0 | ABT1: HAND RECEIPT | ABW1: HAND RECEIPT/ANNEX NUMBER | ACF1: FROM: | ACO1: TO: | ACQ1: Section: | ACV1: =#VALUE! -> #VALUE! | ACX1: HAND RECEIPT | ADA1: HAND RECEIPT/ANNEX NUMBER | ADJ1: FROM: | ADS1: TO: | ADU1: Section: | ADZ1: MAL (V2)'!B | AEB1: HAND RECEIPT | AEE1: HAND RECEIPT/ANNEX NUMBER | AEN1: FROM: | AEW1: TO: | AEY1: Section: | AFD1: MAL (V2)'!B | AFF1: HAND RECEIPT | AFI1: HAND RECEIPT/ANNEX NUMBER | AFR1: FROM: | AGA1: TO: | AGC1: Section: | AGH1: =#VALUE! -> #VALUE! | AGJ1: HAND RECEIPT | AGM1: HAND RECEIPT/ANNEX NUMBER | AGV1: FROM: | AHE1: TO: | AHG1: Section: | AHL1: =#VALUE! -> #VALUE! | AHN1: HAND RECEIPT | AHQ1: HAND RECEIPT/ANNEX NUMBER | AHZ1: FROM: | AII1: TO: | AIK1: Section: | AIP1: =MAL!AFI2 -> 0 | AIR1: HAND RECEIPT | AIU1: HAND RECEIPT/ANNEX NUMBER | AJD1: FROM: | AJM1: TO: | AJO1: Section: | AJT1: =MAL!AFI3 -> 0 | AJV1: HAND RECEIPT | AJY1: HAND RECEIPT/ANNEX NUMBER | AKH1: FROM: | AKQ1: TO: | AKS1: Section: | AKX1: =#VALUE! -> #VALUE! | AKZ1: HAND RECEIPT | ALC1: HAND RECEIPT/ANNEX NUMBER | ALL1: FROM: | ALU1: TO: | ALW1: Section: | AMB1: MAL (V2)'!B | AMD1: HAND RECEIPT | AMG1: HAND RECEIPT/ANNEX NUMBER
A2: For use of this form, see DA PAM 710-2-1 | J2: HHC ARMS ROOM | S2: =#VALUE! -> #VALUE! | W2: =#VALUE! -> #VALUE! | Z2: =MAL!E2 -> 1LT | AB2: NUMBER | AD2: =MAL!D2 -> 1 | AE2: For use of this form, see DA PAM 710-2-1 | AN2: HHC ARMS ROOM | AW2: =#VALUE! -> #VALUE! | BA2: =MAL!G3 -> 0 | BD2: =MAL!E3 -> 0 | BF2: NUMBER | BH2: =MAL!D3 -> 2 | BI2: For use of this form, see DA PAM 710-2-1 | BR2: HHC ARMS ROOM | CA2: =#VALUE! -> #VALUE! | CE2: =#VALUE! -> #VALUE! | CH2: =MAL!E2 -> 1LT | CJ2: NUMBER | CL2: =MAL!D2 -> 1 | CM2: For use of this form, see DA PAM 710-2-1 | CV2: HHC ARMS ROOM | DE2: =#VALUE! -> #VALUE! | DI2: =MAL!G3 -> 0 | DL2: =MAL!E3 -> 0 | DN2: NUMBER | DP2: =MAL!D3 -> 2 | DQ2: For use of this form, see DA PAM 710-2-1 | DZ2: HHC ARMS ROOM | EI2: =#VALUE! -> #VALUE! | EM2: =#VALUE! -> #VALUE! | EP2: =#VALUE! -> #VALUE! | ER2: NUMBER | ET2: =#VALUE! -> #VALUE! | EU2: For use of this form, see DA PAM 710-2-1 | FD2: HHC ARMS ROOM | FM2: MAL (V2)'!H | FQ2: MAL (V2)'!I | FT2: MAL (V2)'!G | FV2: NUMBER | FX2: MAL (V2)'!E | FY2: For use of this form, see DA PAM 710-2-1 | GH2: HHC ARMS ROOM | GQ2: MAL (V2)'!H | GU2: MAL (V2)'!I | GX2: MAL (V2)'!G | GZ2: NUMBER | HB2: MAL (V2)'!E | HC2: For use of this form, see DA PAM 710-2-1 | HL2: HHC ARMS ROOM | HU2: =MAL!HI2 -> 0 | HY2: =MAL!HJ2 -> 0 | IB2: =MAL!HH2 -> 0 | ID2: NUMBER | IF2: =MAL!HF2 -> 0 | IG2: For use of this form, see DA PAM 710-2-1 | IP2: HHC ARMS ROOM | IY2: =#VALUE! -> #VALUE! | JC2: =#VALUE! -> #VALUE! | JF2: =#VALUE! -> #VALUE! | JH2: NUMBER | JJ2: =#VALUE! -> #VALUE! | JK2: For use of this form, see DA PAM 710-2-1 | JT2: HHC ARMS ROOM | KC2: =MAL!HI2 -> 0 | KG2: =MAL!HJ2 -> 0 | KJ2: =MAL!HH2 -> 0 | KL2: NUMBER | KN2: =MAL!HF2 -> 0 | KO2: For use of this form, see DA PAM 710-2-1 | KX2: HHC ARMS ROOM | LG2: =MAL!HI3 -> 0 | LK2: =MAL!HJ3 -> 0 | LN2: =MAL!HH3 -> 0 | LP2: NUMBER | LR2: =MAL!HF3 -> 0 | LS2: For use of this form, see DA PAM 710-2-1 | MB2: HHC ARMS ROOM | MK2: =#VALUE! -> #VALUE! | MO2: =#VALUE! -> #VALUE! | MR2: =#VALUE! -> #VALUE! | MT2: NUMBER | MV2: =#VALUE! -> #VALUE! | MW2: For use of this form, see DA PAM 710-2-1 | NF2: HHC ARMS ROOM | NO2: MAL (V2)'!H | NS2: MAL (V2)'!I | NV2: MAL (V2)'!G | NX2: NUMBER | NZ2: MAL (V2)'!E | OA2: For use of this form, see DA PAM 710-2-1 | OJ2: HHC ARMS ROOM | OS2: MAL (V2)'!H | OW2: MAL (V2)'!I | OZ2: MAL (V2)'!G | PB2: NUMBER | PD2: MAL (V2)'!E | PE2: For use of this form, see DA PAM 710-2-1 | PN2: HHC ARMS ROOM | PW2: =MAL!PK2 -> 0 | QA2: =MAL!PL2 -> 0 | QD2: =MAL!PJ2 -> 0 | QF2: NUMBER | QH2: =MAL!PH2 -> 0 | QI2: For use of this form, see DA PAM 710-2-1 | QR2: HHC ARMS ROOM | RA2: =#VALUE! -> #VALUE! | RE2: =#VALUE! -> #VALUE! | RH2: =#VALUE! -> #VALUE! | RJ2: NUMBER | RL2: =#VALUE! -> #VALUE! | RM2: For use of this form, see DA PAM 710-2-1 | RV2: HHC ARMS ROOM | SE2: =MAL!PK2 -> 0 | SI2: =MAL!PL2 -> 0 | SL2: =MAL!PJ2 -> 0 | SN2: NUMBER | SP2: =MAL!PH2 -> 0 | SQ2: For use of this form, see DA PAM 710-2-1 | SZ2: HHC ARMS ROOM | TI2: =MAL!PK3 -> 0 | TM2: =MAL!PL3 -> 0 | TP2: =MAL!PJ3 -> 0 | TR2: NUMBER | TT2: =MAL!PH3 -> 0 | TU2: For use of this form, see DA PAM 710-2-1 | UD2: HHC ARMS ROOM | UM2: =#VALUE! -> #VALUE! | UQ2: =#VALUE! -> #VALUE! | UT2: =#VALUE! -> #VALUE! | UV2: NUMBER | UX2: =#VALUE! -> #VALUE! | UY2: For use of this form, see DA PAM 710-2-1 | VH2: HHC ARMS ROOM | VQ2: MAL (V2)'!H | VU2: MAL (V2)'!I | VX2: MAL (V2)'!G | VZ2: NUMBER | WB2: MAL (V2)'!E | WC2: For use of this form, see DA PAM 710-2-1 | WL2: HHC ARMS ROOM | WU2: MAL (V2)'!H | WY2: MAL (V2)'!I | XB2: MAL (V2)'!G | XD2: NUMBER | XF2: MAL (V2)'!E | XG2: For use of this form, see DA PAM 710-2-1 | XP2: HHC ARMS ROOM | XY2: =MAL!XM2 -> 0 | YC2: =MAL!XN2 -> 0 | YF2: =MAL!XL2 -> 0 | YH2: NUMBER | YJ2: =MAL!XJ2 -> 0 | YK2: For use of this form, see DA PAM 710-2-1 | YT2: HHC ARMS ROOM | ZC2: =#VALUE! -> #VALUE! | ZG2: =#VALUE! -> #VALUE! | ZJ2: =#VALUE! -> #VALUE! | ZL2: NUMBER | ZN2: =#VALUE! -> #VALUE! | ZO2: For use of this form, see DA PAM 710-2-1 | ZX2: HHC ARMS ROOM | AAG2: =MAL!XM2 -> 0 | AAK2: =MAL!XN2 -> 0 | AAN2: =MAL!XL2 -> 0 | AAP2: NUMBER | AAR2: =MAL!XJ2 -> 0 | AAS2: For use of this form, see DA PAM 710-2-1 | ABB2: HHC ARMS ROOM | ABK2: =MAL!XM3 -> 0 | ABO2: =MAL!XN3 -> 0 | ABR2: =MAL!XL3 -> 0 | ABT2: NUMBER | ABV2: =MAL!XJ3 -> 0 | ABW2: For use of this form, see DA PAM 710-2-1 | ACF2: HHC ARMS ROOM | ACO2: =#VALUE! -> #VALUE! | ACS2: =#VALUE! -> #VALUE! | ACV2: =#VALUE! -> #VALUE! | ACX2: NUMBER | ACZ2: =#VALUE! -> #VALUE! | ADA2: For use of this form, see DA PAM 710-2-1 | ADJ2: HHC ARMS ROOM | ADS2: MAL (V2)'!H | ADW2: MAL (V2)'!I | ADZ2: MAL (V2)'!G | AEB2: NUMBER | AED2: MAL (V2)'!E | AEE2: For use of this form, see DA PAM 710-2-1 | AEN2: HHC ARMS ROOM | AEW2: MAL (V2)'!H | AFA2: MAL (V2)'!I | AFD2: MAL (V2)'!G | AFF2: NUMBER | AFH2: MAL (V2)'!E | AFI2: For use of this form, see DA PAM 710-2-1 | AFR2: HHC ARMS ROOM | AGA2: =MAL!AFO2 -> 0 | AGE2: =MAL!AFP2 -> 0 | AGH2: =MAL!AFN2 -> 0 | AGJ2: NUMBER | AGL2: =MAL!AFL2 -> 0 | AGM2: For use of this form, see DA PAM 710-2-1 | AGV2: HHC ARMS ROOM | AHE2: =#VALUE! -> #VALUE! | AHI2: =#VALUE! -> #VALUE! | AHL2: =#VALUE! -> #VALUE! | AHN2: NUMBER | AHP2: =#VALUE! -> #VALUE! | AHQ2: For use of this form, see DA PAM 710-2-1 | AHZ2: HHC ARMS ROOM | AII2: =MAL!AFO2 -> 0 | AIM2: =MAL!AFP2 -> 0 | AIP2: =MAL!AFN2 -> 0 | AIR2: NUMBER | AIT2: =MAL!AFL2 -> 0 | AIU2: For use of this form, see DA PAM 710-2-1 | AJD2: HHC ARMS ROOM | AJM2: =MAL!AFO3 -> 0 | AJQ2: =MAL!AFP3 -> 0 | AJT2: =MAL!AFN3 -> 0 | AJV2: NUMBER | AJX2: =MAL!AFL3 -> 0 | AJY2: For use of this form, see DA PAM 710-2-1 | AKH2: HHC ARMS ROOM | AKQ2: =#VALUE! -> #VALUE! | AKU2: =#VALUE! -> #VALUE! | AKX2: =#VALUE! -> #VALUE! | AKZ2: NUMBER | ALB2: =#VALUE! -> #VALUE! | ALC2: For use of this form, see DA PAM 710-2-1 | ALL2: HHC ARMS ROOM | ALU2: MAL (V2)'!H | ALY2: MAL (V2)'!I | AMB2: MAL (V2)'!G | AMD2: NUMBER | AMF2: MAL (V2)'!E | AMG2: For use of this form, see DA PAM 710-2-1
A3: The proponent agency is ODCSLOG. | N3: ARMORER | S3: LAST NAME | W3: FIRST NAME | Z3: RANK | AE3: The proponent agency is ODCSLOG. | AR3: ARMORER | AW3: LAST NAME | BA3: FIRST NAME | BD3: RANK | BI3: The proponent agency is ODCSLOG. | BV3: ARMORER | CA3: LAST NAME | CE3: FIRST NAME | CH3: RANK | CM3: The proponent agency is ODCSLOG. | CZ3: ARMORER | DE3: LAST NAME | DI3: FIRST NAME | DL3: RANK | DQ3: The proponent agency is ODCSLOG. | ED3: ARMORER | EI3: LAST NAME | EM3: FIRST NAME | EP3: RANK | EU3: The proponent agency is ODCSLOG. | FH3: ARMORER | FM3: LAST NAME | FQ3: FIRST NAME | FT3: RANK | FY3: The proponent agency is ODCSLOG. | GL3: ARMORER | GQ3: LAST NAME | GU3: FIRST NAME | GX3: RANK | HC3: The proponent agency is ODCSLOG. | HP3: ARMORER | HU3: LAST NAME | HY3: FIRST NAME | IB3: RANK | IG3: The proponent agency is ODCSLOG. | IT3: ARMORER | IY3: LAST NAME | JC3: FIRST NAME | JF3: RANK | JK3: The proponent agency is ODCSLOG. | JX3: ARMORER | KC3: LAST NAME | KG3: FIRST NAME | KJ3: RANK | KO3: The proponent agency is ODCSLOG. | LB3: ARMORER | LG3: LAST NAME | LK3: FIRST NAME | LN3: RANK | LS3: The proponent agency is ODCSLOG. | MF3: ARMORER | MK3: LAST NAME | MO3: FIRST NAME | MR3: RANK | MW3: The proponent agency is ODCSLOG. | NJ3: ARMORER | NO3: LAST NAME | NS3: FIRST NAME | NV3: RANK | OA3: The proponent agency is ODCSLOG. | ON3: ARMORER | OS3: LAST NAME | OW3: FIRST NAME | OZ3: RANK | PE3: The proponent agency is ODCSLOG. | PR3: ARMORER | PW3: LAST NAME | QA3: FIRST NAME | QD3: RANK | QI3: The proponent agency is ODCSLOG. | QV3: ARMORER | RA3: LAST NAME | RE3: FIRST NAME | RH3: RANK | RM3: The proponent agency is ODCSLOG. | RZ3: ARMORER | SE3: LAST NAME | SI3: FIRST NAME | SL3: RANK | SQ3: The proponent agency is ODCSLOG. | TD3: ARMORER | TI3: LAST NAME | TM3: FIRST NAME | TP3: RANK | TU3: The proponent agency is ODCSLOG. | UH3: ARMORER | UM3: LAST NAME | UQ3: FIRST NAME | UT3: RANK | UY3: The proponent agency is ODCSLOG. | VL3: ARMORER | VQ3: LAST NAME | VU3: FIRST NAME | VX3: RANK | WC3: The proponent agency is ODCSLOG. | WP3: ARMORER | WU3: LAST NAME | WY3: FIRST NAME | XB3: RANK | XG3: The proponent agency is ODCSLOG. | XT3: ARMORER | XY3: LAST NAME | YC3: FIRST NAME | YF3: RANK | YK3: The proponent agency is ODCSLOG. | YX3: ARMORER | ZC3: LAST NAME | ZG3: FIRST NAME | ZJ3: RANK | ZO3: The proponent agency is ODCSLOG. | AAB3: ARMORER | AAG3: LAST NAME | AAK3: FIRST NAME | AAN3: RANK | AAS3: The proponent agency is ODCSLOG. | ABF3: ARMORER | ABK3: LAST NAME | ABO3: FIRST NAME | ABR3: RANK | ABW3: The proponent agency is ODCSLOG. | ACJ3: ARMORER | ACO3: LAST NAME | ACS3: FIRST NAME | ACV3: RANK | ADA3: The proponent agency is ODCSLOG. | ADN3: ARMORER | ADS3: LAST NAME | ADW3: FIRST NAME | ADZ3: RANK | AEE3: The proponent agency is ODCSLOG. | AER3: ARMORER | AEW3: LAST NAME | AFA3: FIRST NAME | AFD3: RANK | AFI3: The proponent agency is ODCSLOG. | AFV3: ARMORER | AGA3: LAST NAME | AGE3: FIRST NAME | AGH3: RANK | AGM3: The proponent agency is ODCSLOG. | AGZ3: ARMORER | AHE3: LAST NAME | AHI3: FIRST NAME | AHL3: RANK | AHQ3: The proponent agency is ODCSLOG. | AID3: ARMORER | AII3: LAST NAME | AIM3: FIRST NAME | AIP3: RANK | AIU3: The proponent agency is ODCSLOG. | AJH3: ARMORER | AJM3: LAST NAME | AJQ3: FIRST NAME | AJT3: RANK | AJY3: The proponent agency is ODCSLOG. | AKL3: ARMORER | AKQ3: LAST NAME | AKU3: FIRST NAME | AKX3: RANK | ALC3: The proponent agency is ODCSLOG. | ALP3: ARMORER | ALU3: LAST NAME | ALY3: FIRST NAME | AMB3: RANK | AMG3: The proponent agency is ODCSLOG.
A4: FOR ANNEX/CR ONLY | C4: END ITEM STOCK NUMBER | I4: END ITEM DESCRIPTION | Q4: PUBLICATION NUMBER | X4: PUBLICATION DATE | AB4: QUANTITY | AE4: FOR ANNEX/CR ONLY | AG4: END ITEM STOCK NUMBER | AM4: END ITEM DESCRIPTION | AU4: PUBLICATION NUMBER | BB4: PUBLICATION DATE | BF4: QUANTITY | BI4: FOR ANNEX/CR ONLY | BK4: END ITEM STOCK NUMBER | BQ4: END ITEM DESCRIPTION | BY4: PUBLICATION NUMBER | CF4: PUBLICATION DATE | CJ4: QUANTITY | CM4: FOR ANNEX/CR ONLY | CO4: END ITEM STOCK NUMBER | CU4: END ITEM DESCRIPTION | DC4: PUBLICATION NUMBER | DJ4: PUBLICATION DATE | DN4: QUANTITY | DQ4: FOR ANNEX/CR ONLY | DS4: END ITEM STOCK NUMBER | DY4: END ITEM DESCRIPTION | EG4: PUBLICATION NUMBER | EN4: PUBLICATION DATE | ER4: QUANTITY | EU4: FOR ANNEX/CR ONLY | EW4: END ITEM STOCK NUMBER | FC4: END ITEM DESCRIPTION | FK4: PUBLICATION NUMBER | FR4: PUBLICATION DATE | FV4: QUANTITY | FY4: FOR ANNEX/CR ONLY | GA4: END ITEM STOCK NUMBER | GG4: END ITEM DESCRIPTION | GO4: PUBLICATION NUMBER | GV4: PUBLICATION DATE | GZ4: QUANTITY | HC4: FOR ANNEX/CR ONLY | HE4: END ITEM STOCK NUMBER | HK4: END ITEM DESCRIPTION | HS4: PUBLICATION NUMBER | HZ4: PUBLICATION DATE | ID4: QUANTITY | IG4: FOR ANNEX/CR ONLY | II4: END ITEM STOCK NUMBER | IO4: END ITEM DESCRIPTION | IW4: PUBLICATION NUMBER | JD4: PUBLICATION DATE | JH4: QUANTITY | JK4: FOR ANNEX/CR ONLY | JM4: END ITEM STOCK NUMBER | JS4: END ITEM DESCRIPTION | KA4: PUBLICATION NUMBER | KH4: PUBLICATION DATE | KL4: QUANTITY | KO4: FOR ANNEX/CR ONLY | KQ4: END ITEM STOCK NUMBER | KW4: END ITEM DESCRIPTION | LE4: PUBLICATION NUMBER | LL4: PUBLICATION DATE | LP4: QUANTITY | LS4: FOR ANNEX/CR ONLY | LU4: END ITEM STOCK NUMBER | MA4: END ITEM DESCRIPTION | MI4: PUBLICATION NUMBER | MP4: PUBLICATION DATE | MT4: QUANTITY | MW4: FOR ANNEX/CR ONLY | MY4: END ITEM STOCK NUMBER | NE4: END ITEM DESCRIPTION | NM4: PUBLICATION NUMBER | NT4: PUBLICATION DATE | NX4: QUANTITY | OA4: FOR ANNEX/CR ONLY | OC4: END ITEM STOCK NUMBER | OI4: END ITEM DESCRIPTION | OQ4: PUBLICATION NUMBER | OX4: PUBLICATION DATE | PB4: QUANTITY | PE4: FOR ANNEX/CR ONLY | PG4: END ITEM STOCK NUMBER | PM4: END ITEM DESCRIPTION | PU4: PUBLICATION NUMBER | QB4: PUBLICATION DATE | QF4: QUANTITY | QI4: FOR ANNEX/CR ONLY | QK4: END ITEM STOCK NUMBER | QQ4: END ITEM DESCRIPTION | QY4: PUBLICATION NUMBER | RF4: PUBLICATION DATE | RJ4: QUANTITY | RM4: FOR ANNEX/CR ONLY | RO4: END ITEM STOCK NUMBER | RU4: END ITEM DESCRIPTION | SC4: PUBLICATION NUMBER | SJ4: PUBLICATION DATE | SN4: QUANTITY | SQ4: FOR ANNEX/CR ONLY | SS4: END ITEM STOCK NUMBER | SY4: END ITEM DESCRIPTION | TG4: PUBLICATION NUMBER | TN4: PUBLICATION DATE | TR4: QUANTITY | TU4: FOR ANNEX/CR ONLY | TW4: END ITEM STOCK NUMBER | UC4: END ITEM DESCRIPTION | UK4: PUBLICATION NUMBER | UR4: PUBLICATION DATE | UV4: QUANTITY | UY4: FOR ANNEX/CR ONLY | VA4: END ITEM STOCK NUMBER | VG4: END ITEM DESCRIPTION | VO4: PUBLICATION NUMBER | VV4: PUBLICATION DATE | VZ4: QUANTITY | WC4: FOR ANNEX/CR ONLY | WE4: END ITEM STOCK NUMBER | WK4: END ITEM DESCRIPTION | WS4: PUBLICATION NUMBER | WZ4: PUBLICATION DATE | XD4: QUANTITY | XG4: FOR ANNEX/CR ONLY | XI4: END ITEM STOCK NUMBER | XO4: END ITEM DESCRIPTION | XW4: PUBLICATION NUMBER | YD4: PUBLICATION DATE | YH4: QUANTITY | YK4: FOR ANNEX/CR ONLY | YM4: END ITEM STOCK NUMBER | YS4: END ITEM DESCRIPTION | ZA4: PUBLICATION NUMBER | ZH4: PUBLICATION DATE | ZL4: QUANTITY | ZO4: FOR ANNEX/CR ONLY | ZQ4: END ITEM STOCK NUMBER | ZW4: END ITEM DESCRIPTION | AAE4: PUBLICATION NUMBER | AAL4: PUBLICATION DATE | AAP4: QUANTITY | AAS4: FOR ANNEX/CR ONLY | AAU4: END ITEM STOCK NUMBER | ABA4: END ITEM DESCRIPTION | ABI4: PUBLICATION NUMBER | ABP4: PUBLICATION DATE | ABT4: QUANTITY | ABW4: FOR ANNEX/CR ONLY | ABY4: END ITEM STOCK NUMBER | ACE4: END ITEM DESCRIPTION | ACM4: PUBLICATION NUMBER | ACT4: PUBLICATION DATE | ACX4: QUANTITY | ADA4: FOR ANNEX/CR ONLY | ADC4: END ITEM STOCK NUMBER | ADI4: END ITEM DESCRIPTION | ADQ4: PUBLICATION NUMBER | ADX4: PUBLICATION DATE | AEB4: QUANTITY | AEE4: FOR ANNEX/CR ONLY | AEG4: END ITEM STOCK NUMBER | AEM4: END ITEM DESCRIPTION | AEU4: PUBLICATION NUMBER | AFB4: PUBLICATION DATE | AFF4: QUANTITY | AFI4: FOR ANNEX/CR ONLY | AFK4: END ITEM STOCK NUMBER | AFQ4: END ITEM DESCRIPTION | AFY4: PUBLICATION NUMBER | AGF4: PUBLICATION DATE | AGJ4: QUANTITY | AGM4: FOR ANNEX/CR ONLY | AGO4: END ITEM STOCK NUMBER | AGU4: END ITEM DESCRIPTION | AHC4: PUBLICATION NUMBER | AHJ4: PUBLICATION DATE | AHN4: QUANTITY | AHQ4: FOR ANNEX/CR ONLY | AHS4: END ITEM STOCK NUMBER | AHY4: END ITEM DESCRIPTION | AIG4: PUBLICATION NUMBER | AIN4: PUBLICATION DATE | AIR4: QUANTITY | AIU4: FOR ANNEX/CR ONLY | AIW4: END ITEM STOCK NUMBER | AJC4: END ITEM DESCRIPTION | AJK4: PUBLICATION NUMBER | AJR4: PUBLICATION DATE | AJV4: QUANTITY | AJY4: FOR ANNEX/CR ONLY | AKA4: END ITEM STOCK NUMBER | AKG4: END ITEM DESCRIPTION | AKO4: PUBLICATION NUMBER | AKV4: PUBLICATION DATE | AKZ4: QUANTITY | ALC4: FOR ANNEX/CR ONLY | ALE4: END ITEM STOCK NUMBER | ALK4: END ITEM DESCRIPTION | ALS4: PUBLICATION NUMBER | ALZ4: PUBLICATION DATE | AMD4: QUANTITY | AMG4: FOR ANNEX/CR ONLY | AMI4: END ITEM STOCK NUMBER
A6: STOCK NUMBER | H6: ITEM DESCRIPTION | V6: SEC | W6: UI | X6: QTY AUTH | Y6: g. | Z6: QUANTITY | AE6: STOCK NUMBER | AL6: ITEM DESCRIPTION | AZ6: SEC | BA6: UI | BB6: QTY AUTH | BC6: g. | BD6: QUANTITY | BI6: STOCK NUMBER | BP6: ITEM DESCRIPTION | CD6: SEC | CE6: UI | CF6: QTY AUTH | CG6: g. | CH6: QUANTITY | CM6: STOCK NUMBER | CT6: ITEM DESCRIPTION | DH6: SEC | DI6: UI | DJ6: QTY AUTH | DK6: g. | DL6: QUANTITY | DQ6: STOCK NUMBER | DX6: ITEM DESCRIPTION | EL6: SEC | EM6: UI | EN6: QTY AUTH | EO6: g. | EP6: QUANTITY | EU6: STOCK NUMBER | FB6: ITEM DESCRIPTION | FP6: SEC | FQ6: UI | FR6: QTY AUTH | FS6: g. | FT6: QUANTITY | FY6: STOCK NUMBER | GF6: ITEM DESCRIPTION | GT6: SEC | GU6: UI | GV6: QTY AUTH | GW6: g. | GX6: QUANTITY | HC6: STOCK NUMBER | HJ6: ITEM DESCRIPTION | HX6: SEC | HY6: UI | HZ6: QTY AUTH | IA6: g. | IB6: QUANTITY | IG6: STOCK NUMBER | IN6: ITEM DESCRIPTION | JB6: SEC | JC6: UI | JD6: QTY AUTH | JE6: g. | JF6: QUANTITY | JK6: STOCK NUMBER | JR6: ITEM DESCRIPTION | KF6: SEC | KG6: UI | KH6: QTY AUTH | KI6: g. | KJ6: QUANTITY | KO6: STOCK NUMBER | KV6: ITEM DESCRIPTION | LJ6: SEC | LK6: UI | LL6: QTY AUTH | LM6: g. | LN6: QUANTITY | LS6: STOCK NUMBER | LZ6: ITEM DESCRIPTION | MN6: SEC | MO6: UI | MP6: QTY AUTH | MQ6: g. | MR6: QUANTITY | MW6: STOCK NUMBER | ND6: ITEM DESCRIPTION | NR6: SEC | NS6: UI | NT6: QTY AUTH | NU6: g. | NV6: QUANTITY | OA6: STOCK NUMBER | OH6: ITEM DESCRIPTION | OV6: SEC | OW6: UI | OX6: QTY AUTH | OY6: g. | OZ6: QUANTITY | PE6: STOCK NUMBER | PL6: ITEM DESCRIPTION | PZ6: SEC | QA6: UI | QB6: QTY AUTH | QC6: g. | QD6: QUANTITY | QI6: STOCK NUMBER | QP6: ITEM DESCRIPTION | RD6: SEC | RE6: UI | RF6: QTY AUTH | RG6: g. | RH6: QUANTITY | RM6: STOCK NUMBER | RT6: ITEM DESCRIPTION | SH6: SEC | SI6: UI | SJ6: QTY AUTH | SK6: g. | SL6: QUANTITY | SQ6: STOCK NUMBER | SX6: ITEM DESCRIPTION | TL6: SEC | TM6: UI | TN6: QTY AUTH | TO6: g. | TP6: QUANTITY | TU6: STOCK NUMBER | UB6: ITEM DESCRIPTION | UP6: SEC | UQ6: UI | UR6: QTY AUTH | US6: g. | UT6: QUANTITY | UY6: STOCK NUMBER | VF6: ITEM DESCRIPTION | VT6: SEC | VU6: UI | VV6: QTY AUTH | VW6: g. | VX6: QUANTITY | WC6: STOCK NUMBER | WJ6: ITEM DESCRIPTION | WX6: SEC | WY6: UI | WZ6: QTY AUTH | XA6: g. | XB6: QUANTITY | XG6: STOCK NUMBER | XN6: ITEM DESCRIPTION | YB6: SEC | YC6: UI | YD6: QTY AUTH | YE6: g. | YF6: QUANTITY | YK6: STOCK NUMBER | YR6: ITEM DESCRIPTION | ZF6: SEC | ZG6: UI | ZH6: QTY AUTH | ZI6: g. | ZJ6: QUANTITY | ZO6: STOCK NUMBER | ZV6: ITEM DESCRIPTION | AAJ6: SEC | AAK6: UI | AAL6: QTY AUTH | AAM6: g. | AAN6: QUANTITY | AAS6: STOCK NUMBER | AAZ6: ITEM DESCRIPTION | ABN6: SEC | ABO6: UI | ABP6: QTY AUTH | ABQ6: g. | ABR6: QUANTITY | ABW6: STOCK NUMBER | ACD6: ITEM DESCRIPTION | ACR6: SEC | ACS6: UI | ACT6: QTY AUTH | ACU6: g. | ACV6: QUANTITY | ADA6: STOCK NUMBER | ADH6: ITEM DESCRIPTION | ADV6: SEC | ADW6: UI | ADX6: QTY AUTH | ADY6: g. | ADZ6: QUANTITY | AEE6: STOCK NUMBER | AEL6: ITEM DESCRIPTION | AEZ6: SEC | AFA6: UI | AFB6: QTY AUTH | AFC6: g. | AFD6: QUANTITY | AFI6: STOCK NUMBER | AFP6: ITEM DESCRIPTION | AGD6: SEC | AGE6: UI | AGF6: QTY AUTH | AGG6: g. | AGH6: QUANTITY | AGM6: STOCK NUMBER | AGT6: ITEM DESCRIPTION | AHH6: SEC | AHI6: UI | AHJ6: QTY AUTH | AHK6: g. | AHL6: QUANTITY | AHQ6: STOCK NUMBER | AHX6: ITEM DESCRIPTION | AIL6: SEC | AIM6: UI | AIN6: QTY AUTH | AIO6: g. | AIP6: QUANTITY | AIU6: STOCK NUMBER | AJB6: ITEM DESCRIPTION | AJP6: SEC | AJQ6: UI | AJR6: QTY AUTH | AJS6: g. | AJT6: QUANTITY | AJY6: STOCK NUMBER | AKF6: ITEM DESCRIPTION | AKT6: SEC | AKU6: UI | AKV6: QTY AUTH | AKW6: g. | AKX6: QUANTITY | ALC6: STOCK NUMBER | ALJ6: ITEM DESCRIPTION | ALX6: SEC | ALY6: UI | ALZ6: QTY AUTH | AMA6: g. | AMB6: QUANTITY | AMG6: STOCK NUMBER
U7: * | AY7: * | CC7: * | DG7: * | EK7: * | FO7: * | GS7: * | HW7: * | JA7: * | KE7: * | LI7: * | MM7: * | NQ7: * | OU7: * | PY7: * | RC7: * | SG7: * | TK7: * | UO7: * | VS7: * | WW7: * | YA7: * | ZE7: * | AAI7: * | ABM7: * | ACQ7: * | ADU7: * | AEY7: * | AGC7: * | AHG7: * | AIK7: * | AJO7: * | AKS7: * | ALW7: *
A8: a. | H8: b. | U8: c. | V8: d. | W8: e. | X8: f. | Y8: A | Z8: B | AA8: C | AB8: D | AC8: E | AD8: F | AE8: a. | AL8: b. | AY8: c. | AZ8: d. | BA8: e. | BB8: f. | BC8: A | BD8: B | BE8: C | BF8: D | BG8: E | BH8: F | BI8: a. | BP8: b. | CC8: c. | CD8: d. | CE8: e. | CF8: f. | CG8: A | CH8: B | CI8: C | CJ8: D | CK8: E | CL8: F | CM8: a. | CT8: b. | DG8: c. | DH8: d. | DI8: e. | DJ8: f. | DK8: A | DL8: B | DM8: C | DN8: D | DO8: E | DP8: F | DQ8: a. | DX8: b. | EK8: c. | EL8: d. | EM8: e. | EN8: f. | EO8: A | EP8: B | EQ8: C | ER8: D | ES8: E | ET8: F | EU8: a. | FB8: b. | FO8: c. | FP8: d. | FQ8: e. | FR8: f. | FS8: A | FT8: B | FU8: C | FV8: D | FW8: E | FX8: F | FY8: a. | GF8: b. | GS8: c. | GT8: d. | GU8: e. | GV8: f. | GW8: A | GX8: B | GY8: C | GZ8: D | HA8: E | HB8: F | HC8: a. | HJ8: b. | HW8: c. | HX8: d. | HY8: e. | HZ8: f. | IA8: A | IB8: B | IC8: C | ID8: D | IE8: E | IF8: F | IG8: a. | IN8: b. | JA8: c. | JB8: d. | JC8: e. | JD8: f. | JE8: A | JF8: B | JG8: C | JH8: D | JI8: E | JJ8: F | JK8: a. | JR8: b. | KE8: c. | KF8: d. | KG8: e. | KH8: f. | KI8: A | KJ8: B | KK8: C | KL8: D | KM8: E | KN8: F | KO8: a. | KV8: b. | LI8: c. | LJ8: d. | LK8: e. | LL8: f. | LM8: A | LN8: B | LO8: C | LP8: D | LQ8: E | LR8: F | LS8: a. | LZ8: b. | MM8: c. | MN8: d. | MO8: e. | MP8: f. | MQ8: A | MR8: B | MS8: C | MT8: D | MU8: E | MV8: F | MW8: a. | ND8: b. | NQ8: c. | NR8: d. | NS8: e. | NT8: f. | NU8: A | NV8: B | NW8: C | NX8: D | NY8: E | NZ8: F | OA8: a. | OH8: b. | OU8: c. | OV8: d. | OW8: e. | OX8: f. | OY8: A | OZ8: B | PA8: C | PB8: D | PC8: E | PD8: F | PE8: a. | PL8: b. | PY8: c. | PZ8: d. | QA8: e. | QB8: f. | QC8: A | QD8: B | QE8: C | QF8: D | QG8: E | QH8: F | QI8: a. | QP8: b. | RC8: c. | RD8: d. | RE8: e. | RF8: f. | RG8: A | RH8: B | RI8: C | RJ8: D | RK8: E | RL8: F | RM8: a. | RT8: b. | SG8: c. | SH8: d. | SI8: e. | SJ8: f. | SK8: A | SL8: B | SM8: C | SN8: D | SO8: E | SP8: F | SQ8: a. | SX8: b. | TK8: c. | TL8: d. | TM8: e. | TN8: f. | TO8: A | TP8: B | TQ8: C | TR8: D | TS8: E | TT8: F | TU8: a. | UB8: b. | UO8: c. | UP8: d. | UQ8: e. | UR8: f. | US8: A | UT8: B | UU8: C | UV8: D | UW8: E | UX8: F | UY8: a. | VF8: b. | VS8: c. | VT8: d. | VU8: e. | VV8: f. | VW8: A | VX8: B | VY8: C | VZ8: D | WA8: E | WB8: F | WC8: a. | WJ8: b. | WW8: c. | WX8: d. | WY8: e. | WZ8: f. | XA8: A | XB8: B | XC8: C | XD8: D | XE8: E | XF8: F | XG8: a. | XN8: b. | YA8: c. | YB8: d. | YC8: e. | YD8: f. | YE8: A | YF8: B | YG8: C | YH8: D | YI8: E | YJ8: F | YK8: a. | YR8: b. | ZE8: c. | ZF8: d. | ZG8: e. | ZH8: f. | ZI8: A | ZJ8: B | ZK8: C | ZL8: D | ZM8: E | ZN8: F | ZO8: a. | ZV8: b. | AAI8: c. | AAJ8: d. | AAK8: e. | AAL8: f. | AAM8: A | AAN8: B | AAO8: C | AAP8: D | AAQ8: E | AAR8: F | AAS8: a. | AAZ8: b. | ABM8: c. | ABN8: d. | ABO8: e. | ABP8: f. | ABQ8: A | ABR8: B | ABS8: C | ABT8: D | ABU8: E | ABV8: F | ABW8: a. | ACD8: b. | ACQ8: c. | ACR8: d. | ACS8: e. | ACT8: f. | ACU8: A | ACV8: B | ACW8: C | ACX8: D | ACY8: E | ACZ8: F | ADA8: a. | ADH8: b. | ADU8: c. | ADV8: d. | ADW8: e. | ADX8: f. | ADY8: A | ADZ8: B | AEA8: C | AEB8: D | AEC8: E | AED8: F | AEE8: a. | AEL8: b. | AEY8: c. | AEZ8: d. | AFA8: e. | AFB8: f. | AFC8: A | AFD8: B | AFE8: C | AFF8: D | AFG8: E | AFH8: F | AFI8: a. | AFP8: b. | AGC8: c. | AGD8: d. | AGE8: e. | AGF8: f. | AGG8: A | AGH8: B | AGI8: C | AGJ8: D | AGK8: E | AGL8: F | AGM8: a. | AGT8: b. | AHG8: c. | AHH8: d. | AHI8: e. | AHJ8: f. | AHK8: A | AHL8: B | AHM8: C | AHN8: D | AHO8: E | AHP8: F | AHQ8: a. | AHX8: b. | AIK8: c. | AIL8: d. | AIM8: e. | AIN8: f. | AIO8: A | AIP8: B | AIQ8: C | AIR8: D | AIS8: E | AIT8: F | AIU8: a. | AJB8: b. | AJO8: c. | AJP8: d. | AJQ8: e. | AJR8: f. | AJS8: A | AJT8: B | AJU8: C | AJV8: D | AJW8: E | AJX8: F | AJY8: a. | AKF8: b. | AKS8: c. | AKT8: d. | AKU8: e. | AKV8: f. | AKW8: A | AKX8: B | AKY8: C | AKZ8: D | ALA8: E | ALB8: F | ALC8: a. | ALJ8: b. | ALW8: c. | ALX8: d. | ALY8: e. | ALZ8: f. | AMA8: A | AMB8: B | AMC8: C | AMD8: D | AME8: E | AMF8: F | AMG8: a.
A9: =AD2 -> 1 | H9: =MAL!H2 -> M4 | M9: SERIAL NUMBER: | P9: =MAL!I2 -> W010240 | W9: EA. | X9: 1 | AE9: =BH2 -> 2 | AL9: =MAL!H3 -> M4 | AQ9: SERIAL NUMBER: | AT9: =MAL!I3 -> W011008 | BA9: EA. | BB9: 1 | BI9: =CL2 -> 1 | BP9: =MAL!H2 -> M4 | BU9: SERIAL NUMBER: | BX9: =MAL!I2 -> W010240 | CE9: EA. | CF9: 1 | CM9: =DP2 -> 2 | CT9: =MAL!H3 -> M4 | CY9: SERIAL NUMBER: | DB9: =MAL!I3 -> W011008 | DI9: EA. | DJ9: 1 | DQ9: =ET2 -> #VALUE! | DX9: =#VALUE! -> #VALUE! | EC9: SERIAL NUMBER: | EF9: =#VALUE! -> #VALUE! | EM9: EA. | EN9: 1 | EU9: =FX2 -> MAL (V2)'!E | FB9: MAL (V2)'!J | FG9: SERIAL NUMBER: | FJ9: MAL (V2)'!K | FQ9: EA. | FR9: 1 | FY9: =HB2 -> MAL (V2)'!E | GF9: MAL (V2)'!J | GK9: SERIAL NUMBER: | GN9: MAL (V2)'!K | GU9: EA. | GV9: 1 | HC9: =IF2 -> 0 | HJ9: =MAL!HK2 -> 0 | HO9: SERIAL NUMBER: | HR9: =MAL!HL2 -> 0 | HY9: EA. | HZ9: 1 | IG9: =JJ2 -> #VALUE! | IN9: =#VALUE! -> #VALUE! | IS9: SERIAL NUMBER: | IV9: =#VALUE! -> #VALUE! | JC9: EA. | JD9: 1 | JK9: =KN2 -> 0 | JR9: =MAL!HK2 -> 0 | JW9: SERIAL NUMBER: | JZ9: =MAL!HL2 -> 0 | KG9: EA. | KH9: 1 | KO9: =LR2 -> 0 | KV9: =MAL!HK3 -> 0 | LA9: SERIAL NUMBER: | LD9: =MAL!HL3 -> 0 | LK9: EA. | LL9: 1 | LS9: =MV2 -> #VALUE! | LZ9: =#VALUE! -> #VALUE! | ME9: SERIAL NUMBER: | MH9: =#VALUE! -> #VALUE! | MO9: EA. | MP9: 1 | MW9: =NZ2 -> MAL (V2)'!E | ND9: MAL (V2)'!J | NI9: SERIAL NUMBER: | NL9: MAL (V2)'!K | NS9: EA. | NT9: 1 | OA9: =PD2 -> MAL (V2)'!E | OH9: MAL (V2)'!J | OM9: SERIAL NUMBER: | OP9: MAL (V2)'!K | OW9: EA. | OX9: 1 | PE9: =QH2 -> 0 | PL9: =MAL!PM2 -> 0 | PQ9: SERIAL NUMBER: | PT9: =MAL!PN2 -> 0 | QA9: EA. | QB9: 1 | QI9: =RL2 -> #VALUE! | QP9: =#VALUE! -> #VALUE! | QU9: SERIAL NUMBER: | QX9: =#VALUE! -> #VALUE! | RE9: EA. | RF9: 1 | RM9: =SP2 -> 0 | RT9: =MAL!PM2 -> 0 | RY9: SERIAL NUMBER: | SB9: =MAL!PN2 -> 0 | SI9: EA. | SJ9: 1 | SQ9: =TT2 -> 0 | SX9: =MAL!PM3 -> 0 | TC9: SERIAL NUMBER: | TF9: =MAL!PN3 -> 0 | TM9: EA. | TN9: 1 | TU9: =UX2 -> #VALUE! | UB9: =#VALUE! -> #VALUE! | UG9: SERIAL NUMBER: | UJ9: =#VALUE! -> #VALUE! | UQ9: EA. | UR9: 1 | UY9: =WB2 -> MAL (V2)'!E | VF9: MAL (V2)'!J | VK9: SERIAL NUMBER: | VN9: MAL (V2)'!K | VU9: EA. | VV9: 1 | WC9: =XF2 -> MAL (V2)'!E | WJ9: MAL (V2)'!J | WO9: SERIAL NUMBER: | WR9: MAL (V2)'!K | WY9: EA. | WZ9: 1 | XG9: =YJ2 -> 0 | XN9: =MAL!XO2 -> 0 | XS9: SERIAL NUMBER: | XV9: =MAL!XP2 -> 0 | YC9: EA. | YD9: 1 | YK9: =ZN2 -> #VALUE! | YR9: =#VALUE! -> #VALUE! | YW9: SERIAL NUMBER: | YZ9: =#VALUE! -> #VALUE! | ZG9: EA. | ZH9: 1 | ZO9: =AAR2 -> 0 | ZV9: =MAL!XO2 -> 0 | AAA9: SERIAL NUMBER: | AAD9: =MAL!XP2 -> 0 | AAK9: EA. | AAL9: 1 | AAS9: =ABV2 -> 0 | AAZ9: =MAL!XO3 -> 0 | ABE9: SERIAL NUMBER: | ABH9: =MAL!XP3 -> 0 | ABO9: EA. | ABP9: 1 | ABW9: =ACZ2 -> #VALUE! | ACD9: =#VALUE! -> #VALUE! | ACI9: SERIAL NUMBER: | ACL9: =#VALUE! -> #VALUE! | ACS9: EA. | ACT9: 1 | ADA9: =AED2 -> MAL (V2)'!E | ADH9: MAL (V2)'!J | ADM9: SERIAL NUMBER: | ADP9: MAL (V2)'!K | ADW9: EA. | ADX9: 1 | AEE9: =AFH2 -> MAL (V2)'!E | AEL9: MAL (V2)'!J | AEQ9: SERIAL NUMBER: | AET9: MAL (V2)'!K | AFA9: EA. | AFB9: 1 | AFI9: =AGL2 -> 0 | AFP9: =MAL!AFQ2 -> 0 | AFU9: SERIAL NUMBER: | AFX9: =MAL!AFR2 -> 0 | AGE9: EA. | AGF9: 1 | AGM9: =AHP2 -> #VALUE! | AGT9: =#VALUE! -> #VALUE! | AGY9: SERIAL NUMBER: | AHB9: =#VALUE! -> #VALUE! | AHI9: EA. | AHJ9: 1 | AHQ9: =AIT2 -> 0 | AHX9: =MAL!AFQ2 -> 0 | AIC9: SERIAL NUMBER: | AIF9: =MAL!AFR2 -> 0 | AIM9: EA. | AIN9: 1 | AIU9: =AJX2 -> 0 | AJB9: =MAL!AFQ3 -> 0 | AJG9: SERIAL NUMBER: | AJJ9: =MAL!AFR3 -> 0 | AJQ9: EA. | AJR9: 1 | AJY9: =ALB2 -> #VALUE! | AKF9: =#VALUE! -> #VALUE! | AKK9: SERIAL NUMBER: | AKN9: =#VALUE! -> #VALUE! | AKU9: EA. | AKV9: 1 | ALC9: =AMF2 -> MAL (V2)'!E | ALJ9: MAL (V2)'!J | ALO9: SERIAL NUMBER: | ALR9: MAL (V2)'!K | ALY9: EA. | ALZ9: 1 | AMG9: =ANJ2 -> 0
